{
 "cells": [
  {
   "cell_type": "markdown",
   "metadata": {},
   "source": [
    "# SYNTAX ERROR"
   ]
  },
  {
   "cell_type": "markdown",
   "metadata": {},
   "source": [
    "# DESCRIPTION\n",
    "A syntax error in Python occurs when the code deviates from the correct syntax rules of the Python language. These errors typically happen due to incorrect use of language constructs, such as missing colons, unmatched parentheses, or incorrect indentations."
   ]
  },
  {
   "cell_type": "code",
   "execution_count": 5,
   "metadata": {},
   "outputs": [
    {
     "ename": "SyntaxError",
     "evalue": "expected ':' (678793444.py, line 2)",
     "output_type": "error",
     "traceback": [
      "\u001b[1;36m  Cell \u001b[1;32mIn[5], line 2\u001b[1;36m\u001b[0m\n\u001b[1;33m    if voting_age >= 18\u001b[0m\n\u001b[1;37m                       ^\u001b[0m\n\u001b[1;31mSyntaxError\u001b[0m\u001b[1;31m:\u001b[0m expected ':'\n"
     ]
    }
   ],
   "source": [
    "voting_age=18\n",
    "if voting_age >= 18\n",
    "    print(\"you can vote\")\n",
    "\n",
    " "
   ]
  },
  {
   "cell_type": "markdown",
   "metadata": {},
   "source": [
    "# SOLUTION FOR SYNTAX ERROR:"
   ]
  },
  {
   "cell_type": "code",
   "execution_count": null,
   "metadata": {},
   "outputs": [],
   "source": [
    "voting_age=18\n",
    "if voting_age>=18:\n",
    "    print(\"you can vote\")"
   ]
  },
  {
   "cell_type": "markdown",
   "metadata": {},
   "source": [
    "# TYPE ERROR"
   ]
  },
  {
   "cell_type": "markdown",
   "metadata": {},
   "source": [
    "# DESCRIPTION\n",
    "A TypeError in Python occurs when an operation or function is applied to an object of an inappropriate type."
   ]
  },
  {
   "cell_type": "code",
   "execution_count": 6,
   "metadata": {},
   "outputs": [
    {
     "ename": "TypeError",
     "evalue": "unsupported operand type(s) for +: 'int' and 'str'",
     "output_type": "error",
     "traceback": [
      "\u001b[1;31m---------------------------------------------------------------------------\u001b[0m",
      "\u001b[1;31mTypeError\u001b[0m                                 Traceback (most recent call last)",
      "Cell \u001b[1;32mIn[6], line 6\u001b[0m\n\u001b[0;32m      3\u001b[0m     result\u001b[38;5;241m=\u001b[39m a \u001b[38;5;241m+\u001b[39m b\n\u001b[0;32m      4\u001b[0m     \u001b[38;5;28mprint\u001b[39m(\u001b[38;5;124m\"\u001b[39m\u001b[38;5;124mResult: \u001b[39m\u001b[38;5;124m\"\u001b[39m, result)\n\u001b[1;32m----> 6\u001b[0m \u001b[43maddition\u001b[49m\u001b[43m(\u001b[49m\u001b[43m \u001b[49m\u001b[38;5;241;43m5\u001b[39;49m\u001b[43m \u001b[49m\u001b[43m,\u001b[49m\u001b[38;5;124;43m\"\u001b[39;49m\u001b[38;5;124;43mhey\u001b[39;49m\u001b[38;5;124;43m\"\u001b[39;49m\u001b[43m)\u001b[49m\n",
      "Cell \u001b[1;32mIn[6], line 3\u001b[0m, in \u001b[0;36maddition\u001b[1;34m(a, b)\u001b[0m\n\u001b[0;32m      2\u001b[0m \u001b[38;5;28;01mdef\u001b[39;00m \u001b[38;5;21maddition\u001b[39m(a,b):\n\u001b[1;32m----> 3\u001b[0m     result\u001b[38;5;241m=\u001b[39m \u001b[43ma\u001b[49m\u001b[43m \u001b[49m\u001b[38;5;241;43m+\u001b[39;49m\u001b[43m \u001b[49m\u001b[43mb\u001b[49m\n\u001b[0;32m      4\u001b[0m     \u001b[38;5;28mprint\u001b[39m(\u001b[38;5;124m\"\u001b[39m\u001b[38;5;124mResult: \u001b[39m\u001b[38;5;124m\"\u001b[39m, result)\n",
      "\u001b[1;31mTypeError\u001b[0m: unsupported operand type(s) for +: 'int' and 'str'"
     ]
    }
   ],
   "source": [
    "#Adding a string to an integer\n",
    "def addition(a,b):\n",
    "    result= a + b\n",
    "    print(\"Result: \", result)\n",
    "\n",
    "addition( 5 ,\"hey\")"
   ]
  },
  {
   "cell_type": "markdown",
   "metadata": {},
   "source": [
    "# SOLUTION FOR TYPE ERROR:\n"
   ]
  },
  {
   "cell_type": "code",
   "execution_count": 8,
   "metadata": {},
   "outputs": [
    {
     "name": "stdout",
     "output_type": "stream",
     "text": [
      "Result: 30\n",
      "Error: Both arguments must be numbers.\n"
     ]
    }
   ],
   "source": [
    "def addition(a, b):\n",
    "    try:\n",
    "        result = a + b\n",
    "        print(\"Result:\", result)\n",
    "    except TypeError:\n",
    "        print(\"Error: Both arguments must be numbers.\")\n",
    "\n",
    "addition(10, 20)  \n",
    "addition(10, \"hey\") \n"
   ]
  },
  {
   "cell_type": "markdown",
   "metadata": {},
   "source": [
    "# NAME ERROR"
   ]
  },
  {
   "cell_type": "markdown",
   "metadata": {},
   "source": [
    "# DESCRIPTION\n",
    "A NameError in Python occurs when you try to use a variable or function name that has not been defined"
   ]
  },
  {
   "cell_type": "code",
   "execution_count": 9,
   "metadata": {},
   "outputs": [
    {
     "ename": "NameError",
     "evalue": "name 'number1' is not defined",
     "output_type": "error",
     "traceback": [
      "\u001b[1;31m---------------------------------------------------------------------------\u001b[0m",
      "\u001b[1;31mNameError\u001b[0m                                 Traceback (most recent call last)",
      "Cell \u001b[1;32mIn[9], line 5\u001b[0m\n\u001b[0;32m      2\u001b[0m     total \u001b[38;5;241m=\u001b[39m number1 \u001b[38;5;241m+\u001b[39m number2\n\u001b[0;32m      3\u001b[0m     \u001b[38;5;28mprint\u001b[39m(\u001b[38;5;124m\"\u001b[39m\u001b[38;5;124mTotal:\u001b[39m\u001b[38;5;124m\"\u001b[39m, total)\n\u001b[1;32m----> 5\u001b[0m \u001b[43mprint_total\u001b[49m\u001b[43m(\u001b[49m\u001b[43m)\u001b[49m\n",
      "Cell \u001b[1;32mIn[9], line 2\u001b[0m, in \u001b[0;36mprint_total\u001b[1;34m()\u001b[0m\n\u001b[0;32m      1\u001b[0m \u001b[38;5;28;01mdef\u001b[39;00m \u001b[38;5;21mprint_total\u001b[39m():\n\u001b[1;32m----> 2\u001b[0m     total \u001b[38;5;241m=\u001b[39m \u001b[43mnumber1\u001b[49m \u001b[38;5;241m+\u001b[39m number2\n\u001b[0;32m      3\u001b[0m     \u001b[38;5;28mprint\u001b[39m(\u001b[38;5;124m\"\u001b[39m\u001b[38;5;124mTotal:\u001b[39m\u001b[38;5;124m\"\u001b[39m, total)\n",
      "\u001b[1;31mNameError\u001b[0m: name 'number1' is not defined"
     ]
    }
   ],
   "source": [
    "def print_total():\n",
    "    total = number1 + number2\n",
    "    print(\"Total:\", total)\n",
    "\n",
    "print_total()\n"
   ]
  },
  {
   "cell_type": "markdown",
   "metadata": {},
   "source": [
    "# SOLUTION FOR NAME ERROR:"
   ]
  },
  {
   "cell_type": "code",
   "execution_count": 17,
   "metadata": {},
   "outputs": [
    {
     "name": "stdout",
     "output_type": "stream",
     "text": [
      "Total: 15\n",
      "Caught an error during function call: name 'undefined_variable' is not defined\n"
     ]
    }
   ],
   "source": [
    "def print_total(number1, number2):\n",
    "    try:\n",
    "        total = number1 + number2\n",
    "        print(\"Total:\", total)\n",
    "    except NameError:\n",
    "        print(\"Error: One of the variables is not defined.\")\n",
    "    \n",
    "\n",
    "print_total(5, 10)  \n",
    "try:\n",
    "    print_total(5, undefined_variable)  # This should print \"Error: One of the variables is not defined.\"\n",
    "except NameError as ne:\n",
    "    print(\"Caught an error during function call:\", ne)\n"
   ]
  },
  {
   "cell_type": "markdown",
   "metadata": {},
   "source": [
    "# INDEX ERROR\n",
    "# DECRIPTION:\n",
    "An IndexError in Python occurs when you try to access an index that is out of the range of a list, tuple, or other indexed collections."
   ]
  },
  {
   "cell_type": "code",
   "execution_count": 18,
   "metadata": {},
   "outputs": [
    {
     "ename": "IndexError",
     "evalue": "list index out of range",
     "output_type": "error",
     "traceback": [
      "\u001b[1;31m---------------------------------------------------------------------------\u001b[0m",
      "\u001b[1;31mIndexError\u001b[0m                                Traceback (most recent call last)",
      "Cell \u001b[1;32mIn[18], line 6\u001b[0m\n\u001b[0;32m      3\u001b[0m     \u001b[38;5;28mprint\u001b[39m(\u001b[38;5;124m\"\u001b[39m\u001b[38;5;124mElement at index\u001b[39m\u001b[38;5;124m\"\u001b[39m, index, \u001b[38;5;124m\"\u001b[39m\u001b[38;5;124mis\u001b[39m\u001b[38;5;124m\"\u001b[39m, element)\n\u001b[0;32m      5\u001b[0m my_list \u001b[38;5;241m=\u001b[39m [\u001b[38;5;241m1\u001b[39m, \u001b[38;5;241m2\u001b[39m, \u001b[38;5;241m3\u001b[39m]\n\u001b[1;32m----> 6\u001b[0m \u001b[38;5;28;43mlist\u001b[39;49m\u001b[43m(\u001b[49m\u001b[43mmy_list\u001b[49m\u001b[43m,\u001b[49m\u001b[43m \u001b[49m\u001b[38;5;241;43m5\u001b[39;49m\u001b[43m)\u001b[49m\n",
      "Cell \u001b[1;32mIn[18], line 2\u001b[0m, in \u001b[0;36mlist\u001b[1;34m(lst, index)\u001b[0m\n\u001b[0;32m      1\u001b[0m \u001b[38;5;28;01mdef\u001b[39;00m \u001b[38;5;21mlist\u001b[39m(lst, index):\n\u001b[1;32m----> 2\u001b[0m     element \u001b[38;5;241m=\u001b[39m \u001b[43mlst\u001b[49m\u001b[43m[\u001b[49m\u001b[43mindex\u001b[49m\u001b[43m]\u001b[49m\n\u001b[0;32m      3\u001b[0m     \u001b[38;5;28mprint\u001b[39m(\u001b[38;5;124m\"\u001b[39m\u001b[38;5;124mElement at index\u001b[39m\u001b[38;5;124m\"\u001b[39m, index, \u001b[38;5;124m\"\u001b[39m\u001b[38;5;124mis\u001b[39m\u001b[38;5;124m\"\u001b[39m, element)\n",
      "\u001b[1;31mIndexError\u001b[0m: list index out of range"
     ]
    }
   ],
   "source": [
    "def list(lst, index):\n",
    "    element = lst[index]\n",
    "    print(\"Element at index\", index, \"is\", element)\n",
    "\n",
    "my_list = [1, 2, 3]\n",
    "list(my_list, 5)\n",
    "\n"
   ]
  },
  {
   "cell_type": "markdown",
   "metadata": {},
   "source": [
    "# SOLUTION OF INDEX ERROR:\n",
    "DESCRIPTION:"
   ]
  },
  {
   "cell_type": "code",
   "execution_count": 19,
   "metadata": {},
   "outputs": [
    {
     "name": "stdout",
     "output_type": "stream",
     "text": [
      "Element at index 1 is 2\n",
      "Error: Index 5 is out of range for the list.\n"
     ]
    }
   ],
   "source": [
    "def list(lst, index):\n",
    "    try:\n",
    "        element = lst[index]\n",
    "        print(\"Element at index\", index, \"is\", element)\n",
    "    except IndexError:\n",
    "        print(f\"Error: Index {index} is out of range for the list.\")\n",
    "\n",
    "my_list = [1, 2, 3]\n",
    "list(my_list, 1)\n",
    "list(my_list, 5) \n"
   ]
  },
  {
   "cell_type": "markdown",
   "metadata": {},
   "source": [
    "# KEY ERROR\n",
    "# DESCRIPTION:\n",
    "A KeyError in Python occurs when you try to access a dictionary with a key that does not exist in the dictionary."
   ]
  },
  {
   "cell_type": "code",
   "execution_count": 22,
   "metadata": {},
   "outputs": [
    {
     "ename": "KeyError",
     "evalue": "'address'",
     "output_type": "error",
     "traceback": [
      "\u001b[1;31m---------------------------------------------------------------------------\u001b[0m",
      "\u001b[1;31mKeyError\u001b[0m                                  Traceback (most recent call last)",
      "Cell \u001b[1;32mIn[22], line 6\u001b[0m\n\u001b[0;32m      3\u001b[0m     \u001b[38;5;28mprint\u001b[39m(\u001b[38;5;124m\"\u001b[39m\u001b[38;5;124mValue for key\u001b[39m\u001b[38;5;124m\"\u001b[39m, key, \u001b[38;5;124m\"\u001b[39m\u001b[38;5;124mis\u001b[39m\u001b[38;5;124m\"\u001b[39m, value)\n\u001b[0;32m      5\u001b[0m my_dict \u001b[38;5;241m=\u001b[39m {\u001b[38;5;124m\"\u001b[39m\u001b[38;5;124mName\u001b[39m\u001b[38;5;124m\"\u001b[39m: \u001b[38;5;124m'\u001b[39m\u001b[38;5;124mAayush\u001b[39m\u001b[38;5;124m'\u001b[39m, \u001b[38;5;124m\"\u001b[39m\u001b[38;5;124mAge\u001b[39m\u001b[38;5;124m\"\u001b[39m: \u001b[38;5;241m21\u001b[39m, \u001b[38;5;124m\"\u001b[39m\u001b[38;5;124mProfession\u001b[39m\u001b[38;5;124m\"\u001b[39m: \u001b[38;5;124m'\u001b[39m\u001b[38;5;124mData scientist\u001b[39m\u001b[38;5;124m'\u001b[39m}\n\u001b[1;32m----> 6\u001b[0m \u001b[38;5;28;43mdict\u001b[39;49m\u001b[43m(\u001b[49m\u001b[43mmy_dict\u001b[49m\u001b[43m,\u001b[49m\u001b[43m \u001b[49m\u001b[38;5;124;43m\"\u001b[39;49m\u001b[38;5;124;43maddress\u001b[39;49m\u001b[38;5;124;43m\"\u001b[39;49m\u001b[43m)\u001b[49m\n",
      "Cell \u001b[1;32mIn[22], line 2\u001b[0m, in \u001b[0;36mdict\u001b[1;34m(d, key)\u001b[0m\n\u001b[0;32m      1\u001b[0m \u001b[38;5;28;01mdef\u001b[39;00m \u001b[38;5;21mdict\u001b[39m(d, key):\n\u001b[1;32m----> 2\u001b[0m     value \u001b[38;5;241m=\u001b[39m \u001b[43md\u001b[49m\u001b[43m[\u001b[49m\u001b[43mkey\u001b[49m\u001b[43m]\u001b[49m\n\u001b[0;32m      3\u001b[0m     \u001b[38;5;28mprint\u001b[39m(\u001b[38;5;124m\"\u001b[39m\u001b[38;5;124mValue for key\u001b[39m\u001b[38;5;124m\"\u001b[39m, key, \u001b[38;5;124m\"\u001b[39m\u001b[38;5;124mis\u001b[39m\u001b[38;5;124m\"\u001b[39m, value)\n",
      "\u001b[1;31mKeyError\u001b[0m: 'address'"
     ]
    }
   ],
   "source": [
    "\n",
    "\n",
    "def dict(d, key):\n",
    "    value = d[key]\n",
    "    print(\"Value for key\", key, \"is\", value)\n",
    "\n",
    "my_dict = {\"Name\": 'Aayush', \"Age\": 21, \"Profession\": 'Data scientist'}\n",
    "dict(my_dict, \"address\")\n",
    "\n"
   ]
  },
  {
   "cell_type": "markdown",
   "metadata": {},
   "source": [
    "# SOLUTION FOR KEY ERROR:\n"
   ]
  },
  {
   "cell_type": "code",
   "execution_count": 23,
   "metadata": {},
   "outputs": [
    {
     "name": "stdout",
     "output_type": "stream",
     "text": [
      "Value for key Name is Aayush\n",
      "Error: Key 'address' not found in the dictionary.\n"
     ]
    }
   ],
   "source": [
    "def dict(d, key):\n",
    "    try:\n",
    "        value = d[key]\n",
    "        print(\"Value for key\", key, \"is\", value)\n",
    "    except KeyError:\n",
    "        print(f\"Error: Key '{key}' not found in the dictionary.\")\n",
    "\n",
    "\n",
    "my_dict = {\"Name\": 'Aayush', \"Age\": 21,\"Profession\":'Data scientist' }\n",
    "dict(my_dict, \"Name\")  \n",
    "dict(my_dict, \"address\")  \n"
   ]
  },
  {
   "cell_type": "markdown",
   "metadata": {},
   "source": [
    "# VALUE ERROR\n",
    "# DESCRIPTION:\n",
    "A ValueError in Python occurs when a function receives an argument of the correct type but an inappropriate value"
   ]
  },
  {
   "cell_type": "code",
   "execution_count": 29,
   "metadata": {},
   "outputs": [
    {
     "ename": "ValueError",
     "evalue": "list.remove(x): x not in list",
     "output_type": "error",
     "traceback": [
      "\u001b[1;31m---------------------------------------------------------------------------\u001b[0m",
      "\u001b[1;31mValueError\u001b[0m                                Traceback (most recent call last)",
      "Cell \u001b[1;32mIn[29], line 6\u001b[0m\n\u001b[0;32m      3\u001b[0m     \u001b[38;5;28mprint\u001b[39m(\u001b[38;5;124m\"\u001b[39m\u001b[38;5;124mElement\u001b[39m\u001b[38;5;124m\"\u001b[39m, element, \u001b[38;5;124m\"\u001b[39m\u001b[38;5;124mremoved from the list.\u001b[39m\u001b[38;5;124m\"\u001b[39m)\n\u001b[0;32m      5\u001b[0m my_list \u001b[38;5;241m=\u001b[39m [\u001b[38;5;241m1\u001b[39m, \u001b[38;5;241m2\u001b[39m, \u001b[38;5;241m3\u001b[39m ,\u001b[38;5;241m4\u001b[39m ,\u001b[38;5;241m5\u001b[39m]\n\u001b[1;32m----> 6\u001b[0m \u001b[43mremovelist\u001b[49m\u001b[43m(\u001b[49m\u001b[43mmy_list\u001b[49m\u001b[43m,\u001b[49m\u001b[43m \u001b[49m\u001b[38;5;241;43m7\u001b[39;49m\u001b[43m)\u001b[49m\n",
      "Cell \u001b[1;32mIn[29], line 2\u001b[0m, in \u001b[0;36mremovelist\u001b[1;34m(lst, element)\u001b[0m\n\u001b[0;32m      1\u001b[0m \u001b[38;5;28;01mdef\u001b[39;00m \u001b[38;5;21mremovelist\u001b[39m(lst, element):\n\u001b[1;32m----> 2\u001b[0m     \u001b[43mlst\u001b[49m\u001b[38;5;241;43m.\u001b[39;49m\u001b[43mremove\u001b[49m\u001b[43m(\u001b[49m\u001b[43melement\u001b[49m\u001b[43m)\u001b[49m\n\u001b[0;32m      3\u001b[0m     \u001b[38;5;28mprint\u001b[39m(\u001b[38;5;124m\"\u001b[39m\u001b[38;5;124mElement\u001b[39m\u001b[38;5;124m\"\u001b[39m, element, \u001b[38;5;124m\"\u001b[39m\u001b[38;5;124mremoved from the list.\u001b[39m\u001b[38;5;124m\"\u001b[39m)\n",
      "\u001b[1;31mValueError\u001b[0m: list.remove(x): x not in list"
     ]
    }
   ],
   "source": [
    "def removelist(lst, element):\n",
    "    lst.remove(element)\n",
    "    print(\"Element\", element, \"removed from the list.\")\n",
    "\n",
    "my_list = [1, 2, 3 ,4 ,5]\n",
    "removelist(my_list, 7)\n",
    "\n"
   ]
  },
  {
   "cell_type": "markdown",
   "metadata": {},
   "source": [
    "# SOLUTION FOR VALUE ERROR:"
   ]
  },
  {
   "cell_type": "code",
   "execution_count": 28,
   "metadata": {},
   "outputs": [
    {
     "name": "stdout",
     "output_type": "stream",
     "text": [
      "Element 5 removed from the list\n",
      "Error:Element'7'is not in list\n"
     ]
    }
   ],
   "source": [
    "def removelist(lst, element):\n",
    "    try:\n",
    "      lst.remove(element)\n",
    "      print(\"Element\", element,\"removed from the list\")\n",
    "    except ValueError:\n",
    "      print(f\"Error:Element'{element}'is not in list\")\n",
    "my_list = [1, 2, 3, 4, 5]\n",
    "removelist(my_list,5)\n",
    "removelist(my_list,7)\n"
   ]
  },
  {
   "cell_type": "markdown",
   "metadata": {},
   "source": [
    "# ATTRIBUTE ERROR\n",
    "# DESCRIPTION:\n",
    "An AttributeError in Python occurs when you try to access or call an attribute or method on an object that doesn't have that attribute. This typically happens if you misspell the attribute name, use an attribute that doesn't exist, or use an attribute on an object of the wrong type. "
   ]
  },
  {
   "cell_type": "code",
   "execution_count": 20,
   "metadata": {},
   "outputs": [
    {
     "ename": "AttributeError",
     "evalue": "'MyClass' object has no attribute 'vale'",
     "output_type": "error",
     "traceback": [
      "\u001b[1;31m---------------------------------------------------------------------------\u001b[0m",
      "\u001b[1;31mAttributeError\u001b[0m                            Traceback (most recent call last)",
      "Cell \u001b[1;32mIn[20], line 6\u001b[0m\n\u001b[0;32m      3\u001b[0m         \u001b[38;5;28mself\u001b[39m\u001b[38;5;241m.\u001b[39mvalue \u001b[38;5;241m=\u001b[39m \u001b[38;5;241m10\u001b[39m\n\u001b[0;32m      5\u001b[0m obj \u001b[38;5;241m=\u001b[39m MyClass()\n\u001b[1;32m----> 6\u001b[0m \u001b[38;5;28mprint\u001b[39m(\u001b[43mobj\u001b[49m\u001b[38;5;241;43m.\u001b[39;49m\u001b[43mvale\u001b[49m)\n",
      "\u001b[1;31mAttributeError\u001b[0m: 'MyClass' object has no attribute 'vale'"
     ]
    }
   ],
   "source": [
    "class MyClass:\n",
    "    def __init__(self):\n",
    "        self.value = 10\n",
    "\n",
    "obj = MyClass()\n",
    "print(obj.vale)\n"
   ]
  },
  {
   "cell_type": "markdown",
   "metadata": {},
   "source": [
    "# SOLUTION FOR ATTRIBUTE ERROR:"
   ]
  },
  {
   "cell_type": "code",
   "execution_count": 30,
   "metadata": {},
   "outputs": [
    {
     "name": "stdout",
     "output_type": "stream",
     "text": [
      "10\n"
     ]
    }
   ],
   "source": [
    "class MyClass:\n",
    "    def __init__(self):\n",
    "        self.value = 10\n",
    "\n",
    "obj = MyClass()\n",
    "\n",
    "try:\n",
    "    print(obj.value)  \n",
    "except AttributeError:\n",
    "    print(\"Error: Attribute 'value' not found in the object.\")\n"
   ]
  },
  {
   "cell_type": "markdown",
   "metadata": {},
   "source": [
    "# ZERO DIVISION ERROR\n",
    "# DESCRIPTION:\n",
    "A ZeroDivisionError in Python occurs when you attempt to divide a number by zero, which is mathematically undefined."
   ]
  },
  {
   "cell_type": "code",
   "execution_count": 22,
   "metadata": {},
   "outputs": [
    {
     "ename": "ZeroDivisionError",
     "evalue": "division by zero",
     "output_type": "error",
     "traceback": [
      "\u001b[1;31m---------------------------------------------------------------------------\u001b[0m",
      "\u001b[1;31mZeroDivisionError\u001b[0m                         Traceback (most recent call last)",
      "Cell \u001b[1;32mIn[22], line 4\u001b[0m\n\u001b[0;32m      1\u001b[0m \u001b[38;5;28;01mdef\u001b[39;00m \u001b[38;5;21mdivide\u001b[39m(a, b):\n\u001b[0;32m      2\u001b[0m     \u001b[38;5;28;01mreturn\u001b[39;00m a \u001b[38;5;241m/\u001b[39m b\n\u001b[1;32m----> 4\u001b[0m result \u001b[38;5;241m=\u001b[39m \u001b[43mdivide\u001b[49m\u001b[43m(\u001b[49m\u001b[38;5;241;43m10\u001b[39;49m\u001b[43m,\u001b[49m\u001b[43m \u001b[49m\u001b[38;5;241;43m0\u001b[39;49m\u001b[43m)\u001b[49m\n\u001b[0;32m      5\u001b[0m \u001b[38;5;28mprint\u001b[39m(result)\n",
      "Cell \u001b[1;32mIn[22], line 2\u001b[0m, in \u001b[0;36mdivide\u001b[1;34m(a, b)\u001b[0m\n\u001b[0;32m      1\u001b[0m \u001b[38;5;28;01mdef\u001b[39;00m \u001b[38;5;21mdivide\u001b[39m(a, b):\n\u001b[1;32m----> 2\u001b[0m     \u001b[38;5;28;01mreturn\u001b[39;00m \u001b[43ma\u001b[49m\u001b[43m \u001b[49m\u001b[38;5;241;43m/\u001b[39;49m\u001b[43m \u001b[49m\u001b[43mb\u001b[49m\n",
      "\u001b[1;31mZeroDivisionError\u001b[0m: division by zero"
     ]
    }
   ],
   "source": [
    "def divide(a, b):\n",
    "    return a / b\n",
    "\n",
    "result = divide(10, 0)\n",
    "print(result)"
   ]
  },
  {
   "cell_type": "markdown",
   "metadata": {},
   "source": [
    "# SOLUTION FOR ZERODIVISONERROR:"
   ]
  },
  {
   "cell_type": "code",
   "execution_count": 39,
   "metadata": {},
   "outputs": [
    {
     "name": "stdout",
     "output_type": "stream",
     "text": [
      "5.0\n",
      "Error: Division by zero is not allowed.\n",
      "None\n"
     ]
    }
   ],
   "source": [
    "def divide(a, b):\n",
    "    try:\n",
    "        return a / b\n",
    "    except ZeroDivisionError:\n",
    "        print(\"Error: Division by zero is not allowed.\")\n",
    "        return None\n",
    "    except TypeError:\n",
    "        print(\"Error: Both arguments must be numbers.\")\n",
    "       \n",
    "result = divide(10, 2)  \n",
    "print(result)\n",
    "\n",
    "result = divide(10, 0)  \n",
    "print(result)\n"
   ]
  },
  {
   "cell_type": "markdown",
   "metadata": {},
   "source": [
    "# INDENTATION ERROR\n",
    "# DESCRIPTION:\n",
    "An IndentationError in Python occurs when the indentation of your code does not follow the expected pattern. Proper indentation is crucial in Python because it defines the structure of code blocks, such as loops, conditionals, and function definitions."
   ]
  },
  {
   "cell_type": "code",
   "execution_count": 23,
   "metadata": {},
   "outputs": [
    {
     "ename": "IndentationError",
     "evalue": "expected an indented block after function definition on line 1 (1777158004.py, line 2)",
     "output_type": "error",
     "traceback": [
      "\u001b[1;36m  Cell \u001b[1;32mIn[23], line 2\u001b[1;36m\u001b[0m\n\u001b[1;33m    print(\"Hello, World!\")  # Indentation is incorrect\u001b[0m\n\u001b[1;37m    ^\u001b[0m\n\u001b[1;31mIndentationError\u001b[0m\u001b[1;31m:\u001b[0m expected an indented block after function definition on line 1\n"
     ]
    }
   ],
   "source": [
    "def my_function():\n",
    "print(\"Hello, World!\")  # Indentation is incorrect\n"
   ]
  },
  {
   "cell_type": "markdown",
   "metadata": {},
   "source": [
    "# SOLUTION FOR INDENTATAION ERROR:"
   ]
  },
  {
   "cell_type": "code",
   "execution_count": 41,
   "metadata": {},
   "outputs": [
    {
     "name": "stdout",
     "output_type": "stream",
     "text": [
      "HELLO, WORLD!\n"
     ]
    }
   ],
   "source": [
    "def my_function():\n",
    "    print(\"HELLO, WORLD!\")\n",
    "\n",
    "my_function()"
   ]
  },
  {
   "cell_type": "markdown",
   "metadata": {},
   "source": [
    "# MODULE NOT FOUND ERROR\n",
    "# DESCRIPTION:\n",
    "A ModuleNotFoundError in Python occurs when you try to import a module that cannot be found. This can happen for several reasons, such as the module not being installed, a typo in the module name, or issues with the module's location."
   ]
  },
  {
   "cell_type": "code",
   "execution_count": 24,
   "metadata": {},
   "outputs": [
    {
     "ename": "ModuleNotFoundError",
     "evalue": "No module named 'upflairs'",
     "output_type": "error",
     "traceback": [
      "\u001b[1;31m---------------------------------------------------------------------------\u001b[0m",
      "\u001b[1;31mModuleNotFoundError\u001b[0m                       Traceback (most recent call last)",
      "Cell \u001b[1;32mIn[24], line 1\u001b[0m\n\u001b[1;32m----> 1\u001b[0m \u001b[38;5;28;01mimport\u001b[39;00m \u001b[38;5;21;01mupflairs\u001b[39;00m  \u001b[38;5;66;03m# Typo in module name\u001b[39;00m\n",
      "\u001b[1;31mModuleNotFoundError\u001b[0m: No module named 'upflairs'"
     ]
    }
   ],
   "source": [
    "import upflairs  # Typo in module name\n"
   ]
  },
  {
   "cell_type": "markdown",
   "metadata": {},
   "source": [
    "# SOLUTION FOR MODULE NOT FOUND ERROR:"
   ]
  },
  {
   "cell_type": "code",
   "execution_count": 42,
   "metadata": {},
   "outputs": [
    {
     "name": "stdout",
     "output_type": "stream",
     "text": [
      "Error: The module 'upflairs' was not found. Please check the module name and ensure it is installed.\n"
     ]
    }
   ],
   "source": [
    "try:\n",
    "    import upflairs\n",
    "except ModuleNotFoundError:\n",
    "    print(\"Error: The module 'upflairs' was not found. Please check the module name and ensure it is installed.\")\n",
    "\n",
    "\n",
    " \n"
   ]
  },
  {
   "cell_type": "markdown",
   "metadata": {},
   "source": [
    "# FILE NOT FOUND ERROR\n",
    " # DESCRIPTION:\n",
    "  The FileNotFoundError is commonly raised when trying to open a file that does not exist."
   ]
  },
  {
   "cell_type": "code",
   "execution_count": 43,
   "metadata": {},
   "outputs": [
    {
     "ename": "FileNotFoundError",
     "evalue": "[Errno 2] No such file or directory: 'non_existent_file.txt'",
     "output_type": "error",
     "traceback": [
      "\u001b[1;31m---------------------------------------------------------------------------\u001b[0m",
      "\u001b[1;31mFileNotFoundError\u001b[0m                         Traceback (most recent call last)",
      "Cell \u001b[1;32mIn[43], line 6\u001b[0m\n\u001b[0;32m      3\u001b[0m         content \u001b[38;5;241m=\u001b[39m file\u001b[38;5;241m.\u001b[39mread()\n\u001b[0;32m      4\u001b[0m         \u001b[38;5;28mprint\u001b[39m(content)\n\u001b[1;32m----> 6\u001b[0m \u001b[43mread_file\u001b[49m\u001b[43m(\u001b[49m\u001b[38;5;124;43m\"\u001b[39;49m\u001b[38;5;124;43mnon_existent_file.txt\u001b[39;49m\u001b[38;5;124;43m\"\u001b[39;49m\u001b[43m)\u001b[49m\n",
      "Cell \u001b[1;32mIn[43], line 2\u001b[0m, in \u001b[0;36mread_file\u001b[1;34m(file_path)\u001b[0m\n\u001b[0;32m      1\u001b[0m \u001b[38;5;28;01mdef\u001b[39;00m \u001b[38;5;21mread_file\u001b[39m(file_path):\n\u001b[1;32m----> 2\u001b[0m     \u001b[38;5;28;01mwith\u001b[39;00m \u001b[38;5;28;43mopen\u001b[39;49m\u001b[43m(\u001b[49m\u001b[43mfile_path\u001b[49m\u001b[43m,\u001b[49m\u001b[43m \u001b[49m\u001b[38;5;124;43m'\u001b[39;49m\u001b[38;5;124;43mr\u001b[39;49m\u001b[38;5;124;43m'\u001b[39;49m\u001b[43m)\u001b[49m \u001b[38;5;28;01mas\u001b[39;00m file:\n\u001b[0;32m      3\u001b[0m         content \u001b[38;5;241m=\u001b[39m file\u001b[38;5;241m.\u001b[39mread()\n\u001b[0;32m      4\u001b[0m         \u001b[38;5;28mprint\u001b[39m(content)\n",
      "File \u001b[1;32m~\\AppData\\Roaming\\Python\\Python312\\site-packages\\IPython\\core\\interactiveshell.py:324\u001b[0m, in \u001b[0;36m_modified_open\u001b[1;34m(file, *args, **kwargs)\u001b[0m\n\u001b[0;32m    317\u001b[0m \u001b[38;5;28;01mif\u001b[39;00m file \u001b[38;5;129;01min\u001b[39;00m {\u001b[38;5;241m0\u001b[39m, \u001b[38;5;241m1\u001b[39m, \u001b[38;5;241m2\u001b[39m}:\n\u001b[0;32m    318\u001b[0m     \u001b[38;5;28;01mraise\u001b[39;00m \u001b[38;5;167;01mValueError\u001b[39;00m(\n\u001b[0;32m    319\u001b[0m         \u001b[38;5;124mf\u001b[39m\u001b[38;5;124m\"\u001b[39m\u001b[38;5;124mIPython won\u001b[39m\u001b[38;5;124m'\u001b[39m\u001b[38;5;124mt let you open fd=\u001b[39m\u001b[38;5;132;01m{\u001b[39;00mfile\u001b[38;5;132;01m}\u001b[39;00m\u001b[38;5;124m by default \u001b[39m\u001b[38;5;124m\"\u001b[39m\n\u001b[0;32m    320\u001b[0m         \u001b[38;5;124m\"\u001b[39m\u001b[38;5;124mas it is likely to crash IPython. If you know what you are doing, \u001b[39m\u001b[38;5;124m\"\u001b[39m\n\u001b[0;32m    321\u001b[0m         \u001b[38;5;124m\"\u001b[39m\u001b[38;5;124myou can use builtins\u001b[39m\u001b[38;5;124m'\u001b[39m\u001b[38;5;124m open.\u001b[39m\u001b[38;5;124m\"\u001b[39m\n\u001b[0;32m    322\u001b[0m     )\n\u001b[1;32m--> 324\u001b[0m \u001b[38;5;28;01mreturn\u001b[39;00m \u001b[43mio_open\u001b[49m\u001b[43m(\u001b[49m\u001b[43mfile\u001b[49m\u001b[43m,\u001b[49m\u001b[43m \u001b[49m\u001b[38;5;241;43m*\u001b[39;49m\u001b[43margs\u001b[49m\u001b[43m,\u001b[49m\u001b[43m \u001b[49m\u001b[38;5;241;43m*\u001b[39;49m\u001b[38;5;241;43m*\u001b[39;49m\u001b[43mkwargs\u001b[49m\u001b[43m)\u001b[49m\n",
      "\u001b[1;31mFileNotFoundError\u001b[0m: [Errno 2] No such file or directory: 'non_existent_file.txt'"
     ]
    }
   ],
   "source": [
    "def read_file(file_path):\n",
    "    with open(file_path, 'r') as file:\n",
    "        content = file.read()\n",
    "        print(content)\n",
    "\n",
    "read_file(\"non_exisT_file.txt\")\n"
   ]
  },
  {
   "cell_type": "markdown",
   "metadata": {},
   "source": [
    "# SOLUTION FOR FILE NOT FOUND ERROR:"
   ]
  },
  {
   "cell_type": "code",
   "execution_count": 45,
   "metadata": {},
   "outputs": [
    {
     "name": "stdout",
     "output_type": "stream",
     "text": [
      "Error: The file at 'non_existent_file.txt' was not found.\n"
     ]
    }
   ],
   "source": [
    "def read_file(file_path):\n",
    "    try:\n",
    "        with open(file_path, 'r') as file:\n",
    "            content = file.read()\n",
    "            print(content)\n",
    "    except FileNotFoundError:\n",
    "        print(f\"Error: The file at '{file_path}' was not found.\")\n",
    "    \n",
    "\n",
    "read_file(\"non_existent_file.txt\")  # Should print \"Error: The file at 'non_existent_file.txt' was not found.\"\n"
   ]
  }
 ],
 "metadata": {
  "kernelspec": {
   "display_name": "Python 3",
   "language": "python",
   "name": "python3"
  },
  "language_info": {
   "codemirror_mode": {
    "name": "ipython",
    "version": 3
   },
   "file_extension": ".py",
   "mimetype": "text/x-python",
   "name": "python",
   "nbconvert_exporter": "python",
   "pygments_lexer": "ipython3",
   "version": "3.12.2"
  }
 },
 "nbformat": 4,
 "nbformat_minor": 2
}
